<?xml version="1.0" encoding="UTF-8"?>
<sdf version='1.9'>
  <model name='x500'>
    <pose>0 0 .24 0 0 0</pose>
    <self_collide>false</self_collide>
    <static>false</static>
    <link name="base_link">
      <inertial>
        <mass>2.0</mass>
        <inertia>
          <ixx>0.02166666666666667</ixx>
          <ixy>0</ixy>
          <ixz>0</ixz>
          <iyy>0.02166666666666667</iyy>
          <iyz>0</iyz>
          <izz>0.04000000000000001</izz>
        </inertia>
      </inertial>
      <gravity>true</gravity>
      <velocity_decay/>
      <visual name="base_link_visual">
        <pose>0 0 .025 0 0 3.141592654</pose>
        <geometry>
          <mesh>
            <scale>1 1 1</scale>
            <uri>model://x500/meshes/NXP-HGD-CF.dae</uri>
          </mesh>
        </geometry>
      </visual>
      <visual name="5010_motor_base_0">
        <pose>0.174 0.174 .032 0 0 -.45</pose>
        <geometry>
          <mesh>
            <scale>1 1 1</scale>
            <uri>model://x500/meshes/5010Base.dae</uri>
          </mesh>
        </geometry>
      </visual>
      <visual name="5010_motor_base_1">
        <pose>-0.174 0.174 .032 0 0 -.45</pose>
        <geometry>
          <mesh>
            <scale>1 1 1</scale>
            <uri>model://x500/meshes/5010Base.dae</uri>
          </mesh>
        </geometry>
      </visual>
      <visual name="5010_motor_base_2">
        <pose>0.174 -0.174 .032 0 0 -.45</pose>
        <geometry>
          <mesh>
            <scale>1 1 1</scale>
            <uri>model://x500/meshes/5010Base.dae</uri>
          </mesh>
        </geometry>
      </visual>
      <visual name="5010_motor_base_3">
        <pose>-0.174 -0.174 .032 0 0 -.45</pose>
        <geometry>
          <mesh>
            <scale>1 1 1</scale>
            <uri>model://x500/meshes/5010Base.dae</uri>
          </mesh>
        </geometry>
      </visual>
      <visual name="NXP_FMUK66_FRONT">
        <pose>0.047 .001 .043 1 0 1.57</pose>
        <cast_shadows>false</cast_shadows>
        <geometry>
          <plane>
            <normal>0 0 1</normal>
            <size>.013 .007</size>
          </plane>
        </geometry>
        <material>
          <diffuse>1.0 1.0 1.0</diffuse>
          <specular>1.0 1.0 1.0</specular>
          <pbr>
            <metal>
              <albedo_map>model://x500/materials/textures/nxp.png</albedo_map>
            </metal>
          </pbr>
        </material>
      </visual>
      <visual name="NXP_FMUK66_TOP">
        <pose>-0.023 0 .0515 0 0 -1.57</pose>
        <cast_shadows>false</cast_shadows>
        <geometry>
          <plane>
            <normal>0 0 1</normal>
            <size>.013 .007</size>
          </plane>
        </geometry>
        <material>
          <diffuse>1.0 1.0 1.0</diffuse>
          <specular>1.0 1.0 1.0</specular>
          <pbr>
            <metal>
              <albedo_map>model://x500/materials/textures/nxp.png</albedo_map>
            </metal>
          </pbr>
        </material>
      </visual>
      <visual name="RDDRONE_FMUK66_TOP">
        <pose>-.03 0 .0515 0 0 -1.57</pose>
        <cast_shadows>false</cast_shadows>
        <geometry>
          <plane>
            <normal>0 0 1</normal>
            <size>.032 .0034</size>
          </plane>
        </geometry>
        <material>
          <diffuse>1.0 1.0 1.0</diffuse>
          <specular>1.0 1.0 1.0</specular>
          <pbr>
            <metal>
              <albedo_map>model://x500/materials/textures/rd.png</albedo_map>
            </metal>
          </pbr>
        </material>
      </visual>
      <collision name="base_link_collision_0">
        <pose>0 0 .007 0 0 0</pose>
        <geometry>
          <box>
            <size>0.35355339059327373 0.35355339059327373 0.05</size>
          </box>
        </geometry>
        <surface>
          <contact>
            <ode>
              <min_depth>0.001</min_depth>
              <max_vel>0</max_vel>
            </ode>
          </contact>
          <friction>
            <ode/>
          </friction>
        </surface>
      </collision>
      <collision name="base_link_collision_1">
        <pose>0 -0.098 -.123 -0.35 0 0</pose>
        <geometry>
          <box>
            <size>0.015 0.015 0.21</size>
          </box>
        </geometry>
        <surface>
          <contact>
            <ode>
              <min_depth>0.001</min_depth>
              <max_vel>0</max_vel>
            </ode>
          </contact>
          <friction>
            <ode/>
          </friction>
        </surface>
      </collision>
      <collision name="base_link_collision_2">
        <pose>0 0.098 -.123 0.35 0 0</pose>
        <geometry>
          <box>
            <size>0.015 0.015 0.21</size>
          </box>
        </geometry>
        <surface>
          <contact>
            <ode>
              <min_depth>0.001</min_depth>
              <max_vel>0</max_vel>
            </ode>
          </contact>
          <friction>
            <ode/>
          </friction>
        </surface>
      </collision>
      <collision name="base_link_collision_3">
        <pose>0 -0.132 -.2195 0 0 0</pose>
        <geometry>
          <box>
            <size>0.25 0.015 0.015</size>
          </box>
        </geometry>
        <surface>
          <contact>
            <ode>
              <min_depth>0.001</min_depth>
              <max_vel>0</max_vel>
            </ode>
          </contact>
          <friction>
            <ode/>
          </friction>
        </surface>
      </collision>
      <collision name="base_link_collision_4">
        <pose>0 0.132 -.2195 0 0 0</pose>
        <geometry>
          <box>
            <size>0.25 0.015 0.015</size>
          </box>
        </geometry>
        <surface>
          <contact>
            <ode>
              <min_depth>0.001</min_depth>
              <max_vel>0</max_vel>
            </ode>
          </contact>
          <friction>
            <ode/>
          </friction>
        </surface>
      </collision>
      <sensor name="air_pressure_sensor" type="air_pressure">
        <always_on>1</always_on>
        <update_rate>50</update_rate>
        <air_pressure>
          <pressure>
            <noise type="gaussian">
              <mean>0</mean>
              <stddev>0.01</stddev>
            </noise>
          </pressure>
        </air_pressure>
      </sensor>

      <sensor name="imu_sensor" type="imu">
        <always_on>1</always_on>
        <update_rate>250</update_rate>
      </sensor>

      <!-- <visual name="camera0_visual"> -->
      <!--   <pose>0 0 0.5 0 0 0</pose> -->
      <!--   <geometry> -->
      <!--     <box> -->
      <!--       <size>0.05 0.03 0.03</size> -->
      <!--     </box> -->
      <!--   </geometry> -->
      <!-- </visual> -->
      <!-- <sensor name="camera0" type="camera"> -->
      <!--   <pose>0 0 0.5 0 0 0</pose> -->
      <!--   <topic>/mav/camera0</topic> -->
      <!--   <camera> -->
      <!--     <horizontal_fov>1.047</horizontal_fov> -->
      <!--     <image> -->
      <!--       <width>640</width> -->
      <!--       <height>640</height> -->
      <!--     </image> -->
      <!--   </camera> -->
      <!--   <always_on>1</always_on> -->
      <!--   <update_rate>20</update_rate> -->
      <!--   <visualize>true</visualize> -->
      <!-- </sensor> -->
    </link>
    <link name="rotor_0">
      <gravity>true</gravity>
      <self_collide>false</self_collide>
      <velocity_decay/>
      <pose>0.174 -0.174 0.06 0 0 0</pose>
      <inertial>
          <mass>0.016076923076923075</mass>
          <inertia>
            <ixx>3.8464910483993325e-07</ixx>
            <iyy>2.6115851691700804e-05</iyy>
            <izz>2.649858234714004e-05</izz>
          </inertia>
        </inertial>
      <visual name="rotor_0_visual">
        <pose>-0.022 -0.14638461538461536 -0.016 0 0 0</pose>
        <geometry>
          <mesh>
            <scale>0.8461538461538461 0.8461538461538461 0.8461538461538461</scale>
            <uri>model://x500/meshes/1345_prop_ccw.stl</uri>
          </mesh>
        </geometry>
        <material>
          <script>
            <name>Gazebo/DarkGrey</name>
            <uri>file://media/materials/scripts/gazebo.material</uri>
          </script>
        </material>
      </visual>
      <visual name="rotor_0_visual_motor_bell">
        <pose>0 0 -.032 0 0 0</pose>
        <geometry>
          <mesh>
            <scale>1 1 1</scale>
            <uri>model://x500/meshes/5010Bell.dae</uri>
          </mesh>
        </geometry>
      </visual>
      <collision name="rotor_0_collision">
        <pose>0 0 0 0 0 0 </pose>
        <geometry>
          <box>
            <size>0.2792307692307692 0.016923076923076923 0.0008461538461538462</size>
          </box>
        </geometry>
        <surface>
          <contact>
            <ode>
              <min_depth>0.001</min_depth>
              <max_vel>0</max_vel>
            </ode>
          </contact>
          <friction>
            <ode/>
          </friction>
        </surface>
      </collision>
    </link>
    <joint name="rotor_0_joint" type="revolute">
      <parent>base_link</parent>
      <child>rotor_0</child>
      <axis>
        <xyz>0 0 1</xyz>
        <limit>
          <lower>-1e+16</lower>
          <upper>1e+16</upper>
        </limit>
        <dynamics>
          <spring_reference>0</spring_reference>
          <spring_stiffness>0</spring_stiffness>
        </dynamics>
      </axis>
    </joint>
    <link name="rotor_1">
      <gravity>true</gravity>
      <self_collide>false</self_collide>
      <velocity_decay/>
      <pose>-0.174 0.174 0.06 0 0 0</pose>
      <inertial>
          <mass>0.016076923076923075</mass>
          <inertia>
            <ixx>3.8464910483993325e-07</ixx>
            <iyy>2.6115851691700804e-05</iyy>
            <izz>2.649858234714004e-05</izz>
          </inertia>
        </inertial>
      <visual name="rotor_1_visual">
        <pose>-0.022 -0.14638461538461536 -0.016 0 0 0</pose>
        <geometry>
          <mesh>
            <scale>0.8461538461538461 0.8461538461538461 0.8461538461538461</scale>
            <uri>model://x500/meshes/1345_prop_ccw.stl</uri>
          </mesh>
        </geometry>
        <material>
          <script>
            <name>Gazebo/DarkGrey</name>
            <uri>file://media/materials/scripts/gazebo.material</uri>
          </script>
        </material>
      </visual>
      <visual name="rotor_1_visual_motor_top">
        <pose>0 0 -.032 0 0 0</pose>
        <geometry>
          <mesh>
            <scale>1 1 1</scale>
            <uri>model://x500/meshes/5010Bell.dae</uri>
          </mesh>
        </geometry>
      </visual>
      <collision name="rotor_1_collision">
        <pose>0 0 0 0 0 0 </pose>
        <geometry>
          <box>
            <size>0.2792307692307692 0.016923076923076923 0.0008461538461538462</size>
          </box>
        </geometry>
        <surface>
          <contact>
            <ode>
              <min_depth>0.001</min_depth>
              <max_vel>0</max_vel>
            </ode>
          </contact>
          <friction>
            <ode/>
          </friction>
        </surface>
      </collision>
    </link>
    <joint name="rotor_1_joint" type="revolute">
      <parent>base_link</parent>
      <child>rotor_1</child>
      <axis>
        <xyz>0 0 1</xyz>
        <limit>
          <lower>-1e+16</lower>
          <upper>1e+16</upper>
        </limit>
        <dynamics>
          <spring_reference>0</spring_reference>
          <spring_stiffness>0</spring_stiffness>
        </dynamics>
      </axis>
    </joint>
    <link name="rotor_2">
      <gravity>true</gravity>
      <self_collide>false</self_collide>
      <velocity_decay/>
      <pose>0.174 0.174 0.06 0 0 0</pose>
      <inertial>
          <mass>0.016076923076923075</mass>
          <inertia>
            <ixx>3.8464910483993325e-07</ixx>
            <iyy>2.6115851691700804e-05</iyy>
            <izz>2.649858234714004e-05</izz>
          </inertia>
        </inertial>
      <visual name="rotor_2_visual">
        <pose>-0.022 -0.14638461538461536 -0.016 0 0 0</pose>
        <geometry>
          <mesh>
            <scale>0.8461538461538461 0.8461538461538461 0.8461538461538461</scale>
            <uri>model://x500/meshes/1345_prop_cw.stl</uri>
          </mesh>
        </geometry>
        <material>
          <script>
            <name>Gazebo/DarkGrey</name>
            <uri>file://media/materials/scripts/gazebo.material</uri>
          </script>
        </material>
      </visual>
      <visual name="rotor_2_visual_motor_top">
        <pose>0 0 -.032 0 0 0</pose>
        <geometry>
          <mesh>
            <scale>1 1 1</scale>
            <uri>model://x500/meshes/5010Bell.dae</uri>
          </mesh>
        </geometry>
      </visual>
      <collision name="rotor_2_collision">
        <pose>0 0 0 0 0 0 </pose>
        <geometry>
          <box>
            <size>0.2792307692307692 0.016923076923076923 0.0008461538461538462</size>
          </box>
        </geometry>
        <surface>
          <contact>
            <ode>
              <min_depth>0.001</min_depth>
              <max_vel>0</max_vel>
            </ode>
          </contact>
          <friction>
            <ode/>
          </friction>
        </surface>
      </collision>
    </link>
    <joint name="rotor_2_joint" type="revolute">
      <parent>base_link</parent>
      <child>rotor_2</child>
      <axis>
        <xyz>0 0 1</xyz>
        <limit>
          <lower>-1e+16</lower>
          <upper>1e+16</upper>
        </limit>
        <dynamics>
          <spring_reference>0</spring_reference>
          <spring_stiffness>0</spring_stiffness>
        </dynamics>
      </axis>
    </joint>
    <link name="rotor_3">
      <gravity>true</gravity>
      <self_collide>false</self_collide>
      <velocity_decay/>
      <pose>-0.174 -0.174 0.06 0 0 0</pose>
      <inertial>
          <mass>0.016076923076923075</mass>
          <inertia>
            <ixx>3.8464910483993325e-07</ixx>
            <iyy>2.6115851691700804e-05</iyy>
            <izz>2.649858234714004e-05</izz>
          </inertia>
        </inertial>
      <visual name="rotor_3_visual">
        <pose>-0.022 -0.14638461538461536 -0.016 0 0 0</pose>
        <geometry>
          <mesh>
            <scale>0.8461538461538461 0.8461538461538461 0.8461538461538461</scale>
            <uri>model://x500/meshes/1345_prop_cw.stl</uri>
          </mesh>
        </geometry>
        <material>
          <script>
            <name>Gazebo/DarkGrey</name>
            <uri>file://media/materials/scripts/gazebo.material</uri>
          </script>
        </material>
      </visual>
      <visual name="rotor_3_visual_motor_top">
        <pose>0 0 -.032 0 0 0</pose>
        <geometry>
          <mesh>
            <scale>1 1 1</scale>
            <uri>model://x500/meshes/5010Bell.dae</uri>
          </mesh>
        </geometry>
      </visual>
      <collision name="rotor_3_collision">
        <pose>0 0 0 0 0 0 </pose>
        <geometry>
          <box>
            <size>0.2792307692307692 0.016923076923076923 0.0008461538461538462</size>
          </box>
        </geometry>
        <surface>
          <contact>
            <ode>
              <min_depth>0.001</min_depth>
              <max_vel>0</max_vel>
            </ode>
          </contact>
          <friction>
            <ode/>
          </friction>
        </surface>
      </collision>
    </link>
    <joint name="rotor_3_joint" type="revolute">
      <parent>base_link</parent>
      <child>rotor_3</child>
      <axis>
        <xyz>0 0 1</xyz>
        <limit>
          <lower>-1e+16</lower>
          <upper>1e+16</upper>
        </limit>
        <dynamics>
          <spring_reference>0</spring_reference>
          <spring_stiffness>0</spring_stiffness>
        </dynamics>
      </axis>
    </joint>

    <!-- Motor Model Plugins -->
    <plugin
      filename="gz-sim-multicopter-motor-model-system"
      name="gz::sim::systems::MulticopterMotorModel">
      <robotNamespace>x500</robotNamespace>
      <jointName>rotor_0_joint</jointName>
      <linkName>rotor_0</linkName>
      <turningDirection>ccw</turningDirection>
      <timeConstantUp>0.0125</timeConstantUp>
      <timeConstantDown>0.025</timeConstantDown>
      <maxRotVelocity>800.0</maxRotVelocity>
      <motorConstant>8.54858e-06</motorConstant>
      <momentConstant>0.016</momentConstant>
      <commandSubTopic>motor_speed/cmd</commandSubTopic>
      <motorNumber>0</motorNumber>
      <rotorDragCoefficient>8.06428e-05</rotorDragCoefficient>
      <rollingMomentCoefficient>1e-06</rollingMomentCoefficient>
      <motorSpeedPubTopic>motor_speed/0</motorSpeedPubTopic>
      <rotorVelocitySlowdownSim>10</rotorVelocitySlowdownSim>
      <motorType>velocity</motorType>
    </plugin>
    <plugin
      filename="gz-sim-multicopter-motor-model-system"
      name="gz::sim::systems::MulticopterMotorModel">
      <robotNamespace>x500</robotNamespace>
      <jointName>rotor_1_joint</jointName>
      <linkName>rotor_1</linkName>
      <turningDirection>ccw</turningDirection>
      <timeConstantUp>0.0125</timeConstantUp>
      <timeConstantDown>0.025</timeConstantDown>
      <maxRotVelocity>800.0</maxRotVelocity>
      <motorConstant>8.54858e-06</motorConstant>
      <momentConstant>0.016</momentConstant>
      <commandSubTopic>motor_speed/cmd</commandSubTopic>
      <motorNumber>1</motorNumber>
      <rotorDragCoefficient>8.06428e-05</rotorDragCoefficient>
      <rollingMomentCoefficient>1e-06</rollingMomentCoefficient>
      <motorSpeedPubTopic>motor_speed/1</motorSpeedPubTopic>
      <rotorVelocitySlowdownSim>10</rotorVelocitySlowdownSim>
      <motorType>velocity</motorType>
    </plugin>
    <plugin
      filename="gz-sim-multicopter-motor-model-system"
      name="gz::sim::systems::MulticopterMotorModel">
      <robotNamespace>x500</robotNamespace>
      <jointName>rotor_2_joint</jointName>
      <linkName>rotor_2</linkName>
      <turningDirection>cw</turningDirection>
      <timeConstantUp>0.0125</timeConstantUp>
      <timeConstantDown>0.025</timeConstantDown>
      <maxRotVelocity>800.0</maxRotVelocity>
      <motorConstant>8.54858e-06</motorConstant>
      <momentConstant>0.016</momentConstant>
      <commandSubTopic>motor_speed/cmd</commandSubTopic>
      <motorNumber>2</motorNumber>
      <rotorDragCoefficient>8.06428e-05</rotorDragCoefficient>
      <rollingMomentCoefficient>1e-06</rollingMomentCoefficient>
      <motorSpeedPubTopic>motor_speed/2</motorSpeedPubTopic>
      <rotorVelocitySlowdownSim>10</rotorVelocitySlowdownSim>
      <motorType>velocity</motorType>
    </plugin>
    <plugin
      filename="gz-sim-multicopter-motor-model-system"
      name="gz::sim::systems::MulticopterMotorModel">
      <robotNamespace>x500</robotNamespace>
      <jointName>rotor_3_joint</jointName>
      <linkName>rotor_3</linkName>
      <turningDirection>cw</turningDirection>
      <timeConstantUp>0.0125</timeConstantUp>
      <timeConstantDown>0.025</timeConstantDown>
      <maxRotVelocity>800.0</maxRotVelocity>
      <motorConstant>8.54858e-06</motorConstant>
      <momentConstant>0.016</momentConstant>
      <commandSubTopic>motor_speed/cmd</commandSubTopic>
      <motorNumber>3</motorNumber>
      <rotorDragCoefficient>8.06428e-05</rotorDragCoefficient>
      <rollingMomentCoefficient>1e-06</rollingMomentCoefficient>
      <motorSpeedPubTopic>motor_speed/3</motorSpeedPubTopic>
      <rotorVelocitySlowdownSim>10</rotorVelocitySlowdownSim>
      <motorType>velocity</motorType>
    </plugin>

    <!-- Velocity Controller Plugin -->
    <plugin
      filename="gz-sim-multicopter-control-system"
      name="gz::sim::systems::MulticopterVelocityControl">
      <robotNamespace>x500</robotNamespace>
      <commandSubTopic>twist/cmd</commandSubTopic>
      <enableSubTopic>enable</enableSubTopic>
      <comLinkName>base_link</comLinkName>
      <velocityGain>2.7 2.7 2.7</velocityGain>
      <attitudeGain>2 3 0.15</attitudeGain>
      <angularRateGain>0.4 0.52 0.18</angularRateGain>
      <maximumLinearAcceleration>2 2 2</maximumLinearAcceleration>

      <rotorConfiguration>
        <rotor>
          <jointName>rotor_0_joint</jointName>
          <forceConstant>8.54858e-06</forceConstant>
          <momentConstant>0.016</momentConstant>
          <direction>1</direction>
        </rotor>
        <rotor>
          <jointName>rotor_1_joint</jointName>
          <forceConstant>8.54858e-06</forceConstant>
          <momentConstant>0.016</momentConstant>
          <direction>1</direction>
        </rotor>
        <rotor>
          <jointName>rotor_2_joint</jointName>
          <forceConstant>8.54858e-06</forceConstant>
          <momentConstant>0.016</momentConstant>
          <direction>-1</direction>
        </rotor>
        <rotor>
          <jointName>rotor_3_joint</jointName>
          <forceConstant>8.54858e-06</forceConstant>
          <momentConstant>0.016</momentConstant>
          <direction>-1</direction>
        </rotor>
      </rotorConfiguration>
    </plugin>

    <!-- Odometry Plugin -->
    <plugin
      filename="gz-sim-odometry-publisher-system"
      name="gz::sim::systems::OdometryPublisher">
      <dimensions>3</dimensions>
      <odom_topic>/x500/odom/state</odom_topic>
      <tf_topic>/x500/pose/state</tf_topic>
    </plugin>

    <!-- Position Controller Plugin -->
    <plugin
        filename="libMavPositionControllerPlugin"
        name="MavPositionControllerPlugin">
      <poseStateTopic>/x500/pose/state</poseStateTopic>
      <positionCommandTopic>/x500/position/cmd</positionCommandTopic>
      <yawCommandTopic>/x500/yaw/cmd</yawCommandTopic>
      <twistCommandTopic>/x500/twist/cmd</twistCommandTopic>
    </plugin>

    <!-- GIMBAL -->
    <!-- Gimbal base -->
    <link name="gimbal_base">
      <pose relative_to="base_link">0.1 0.0 -0.02 3.1415 0.0 0.0</pose>
      <inertial>
        <inertia>
          <ixx>0.001</ixx>
          <ixy>0</ixy>
          <ixz>0</ixz>
          <iyy>0.001</iyy>
          <iyz>0</iyz>
          <izz>0.001</izz>
        </inertia>
        <mass>0.000001</mass>
      </inertial>

      <visual name="gimbal_base_visual">
        <geometry>
          <box>
            <size>0.1 0.1 0.01</size>
          </box>
        </geometry>

        <material>
            <ambient>0.0 0.0 0.0 1</ambient>
            <diffuse>0.0 0.0 0.0 1</diffuse>
            <specular>0.0 0.0 0.0 1</specular>
        </material>
      </visual>

      <collision name="gimbal_base_collision">
        <geometry>
          <box>
            <size>0.1 0.1 0.01</size>
          </box>
        </geometry>
      </collision>
    </link>

    <!-- base_link to gimbal_base joint -->
    <joint name="base_link_to_gimbal_base_joint" type="fixed">
      <parent>base_link</parent>
      <child>gimbal_base</child>
    </joint>

    <!-- Gimbal yaw motor -->
    <link name="gimbal_yaw">
      <pose relative_to="gimbal_base">0.0 0.0 0.01225 0.0 0.0 0.0</pose>

      <inertial>
        <inertia>
          <ixx>0.000001</ixx>
          <ixy>0</ixy>
          <ixz>0</ixz>
          <iyy>0.000001</iyy>
          <iyz>0</iyz>
          <izz>0.000001</izz>
        </inertia>
        <mass>0.00001</mass>
      </inertial>

      <visual name="gimbal_yaw_visual">
        <geometry>
          <cylinder>
            <radius>0.015</radius>
            <length>0.015</length>
          </cylinder>
        </geometry>

        <material>
            <ambient>1.0 0.0 0.0 1</ambient>
            <diffuse>1.0 0.0 0.0 1</diffuse>
            <specular>1.0 0.0 0.0 1</specular>
        </material>
      </visual>

      <collision name="gimbal_yaw_collision">
        <geometry>
          <cylinder>
            <radius>0.015</radius>
            <length>0.015</length>
          </cylinder>
        </geometry>
      </collision>
    </link>

    <!-- Gimbal base to yaw joint -->
    <joint name="gimbal_base_to_gimbal_yaw_joint" type="fixed">
      <parent>gimbal_base</parent>
      <child>gimbal_yaw</child>
    </joint>

    <!-- Gimbal yaw joint -->
    <joint name="gimbal_yaw_joint" type="revolute">
      <parent>gimbal_yaw</parent>
      <child>gimbal_yaw_bar</child>
      <axis>
        <xyz>0 0 1</xyz>
        <dynamics>
          <damping>1.0</damping>
        </dynamics>
      </axis>
    </joint>
    <plugin
        filename="gz-sim-joint-position-controller-system"
        name="gz::sim::systems::JointPositionController">
      <joint_name>gimbal_yaw_joint</joint_name>
      <topic>/gimbal/joint0/cmd</topic>
      <p_gain>100</p_gain>
      <i_gain>0.0</i_gain>
      <d_gain>1</d_gain>
      <i_max>1</i_max>
      <i_min>-1</i_min>
      <cmd_max>1000</cmd_max>
      <cmd_min>-1000</cmd_min>
    </plugin>
    <plugin
        filename="gz-sim-joint-state-publisher-system"
        name="gz::sim::systems::JointStatePublisher">
      <joint_name>gimbal_yaw_joint</joint_name>
      <topic>/gimbal/joint0/state</topic>
    </plugin>

    <!-- Gimbal yaw bar -->
    <link name="gimbal_yaw_bar">
      <pose relative_to="gimbal_yaw">0.0 0.0 0.0325 0.0 0.0 0.0</pose>

      <inertial>
        <inertia>
          <ixx>0.000001</ixx>
          <ixy>0</ixy>
          <ixz>0</ixz>
          <iyy>0.000001</iyy>
          <iyz>0</iyz>
          <izz>0.000001</izz>
        </inertia>
        <mass>0.00001</mass>
      </inertial>

      <visual name="gimbal_yaw_bar_visual">
        <geometry>
          <box>
            <size>0.02 0.02 0.05</size>
          </box>
        </geometry>

        <material>
            <ambient>0.0 0.0 0.0 1</ambient>
            <diffuse>0.0 0.0 0.0 1</diffuse>
            <specular>0.0 0.0 0.0 1</specular>
        </material>
      </visual>

      <collision name="gimbal_yaw_bar_collision">
        <pose>0.0 0.0 0.0 0 0 0</pose>
        <geometry>
          <box>
            <size>0.02 0.02 0.05</size>
          </box>
        </geometry>
      </collision>
    </link>

    <!-- Gimbal roll motor -->
    <link name="gimbal_roll">
      <pose relative_to="gimbal_yaw_bar">0.0175 0.0 0.01 0.0 1.5708 0.0</pose>

      <inertial>
        <inertia>
          <ixx>0.000001</ixx>
          <ixy>0</ixy>
          <ixz>0</ixz>
          <iyy>0.000001</iyy>
          <iyz>0</iyz>
          <izz>0.000001</izz>
        </inertia>
        <mass>0.00001</mass>
      </inertial>

      <visual name="gimbal_roll_visual">
        <geometry>
          <cylinder>
            <radius>0.015</radius>
            <length>0.015</length>
          </cylinder>
        </geometry>

        <material>
            <ambient>1.0 0.0 0.0 1</ambient>
            <diffuse>1.0 0.0 0.0 1</diffuse>
            <specular>1.0 0.0 0.0 1</specular>
        </material>
      </visual>

      <collision name="gimbal_roll_collision">
        <geometry>
          <cylinder>
            <radius>0.015</radius>
            <length>0.015</length>
          </cylinder>
        </geometry>
      </collision>
    </link>

    <!-- Gimbal roll bar -->
    <link name="gimbal_roll_bar">
      <pose relative_to="gimbal_roll">0.0 0.0 0.0325 0.0 0.0 0.0</pose>

      <inertial>
        <inertia>
          <ixx>0.001</ixx>
          <ixy>0</ixy>
          <ixz>0</ixz>
          <iyy>0.001</iyy>
          <iyz>0</iyz>
          <izz>0.001</izz>
        </inertia>
        <mass>0.0001</mass>
      </inertial>

      <visual name="gimbal_roll_bar_visual">
        <geometry>
          <box>
            <size>0.02 0.02 0.05</size>
          </box>
        </geometry>

        <material>
            <ambient>0.0 0.0 0.0 1</ambient>
            <diffuse>0.0 0.0 0.0 1</diffuse>
            <specular>0.0 0.0 0.0 1</specular>
        </material>
      </visual>

      <collision name="gimbal_roll_bar_collision">
        <pose>0.0 0.0 0.0 0 0 0</pose>
        <geometry>
          <box>
            <size>0.02 0.02 0.05</size>
          </box>
        </geometry>
      </collision>
    </link>

    <!-- Gimbal yaw bar to roll joint -->
    <joint name="gimbal_yaw_bar_to_gimbal_roll_joint" type="fixed">
      <parent>gimbal_yaw_bar</parent>
      <child>gimbal_roll</child>
    </joint>

    <!-- Gimbal roll joint -->
    <joint name="gimbal_roll_joint" type="revolute">
      <parent>gimbal_roll</parent>
      <child>gimbal_roll_bar</child>
      <axis>
        <xyz>0 0 1</xyz>
        <dynamics>
          <damping>1.0</damping>
        </dynamics>
      </axis>
    </joint>
    <plugin
        filename="gz-sim-joint-position-controller-system"
        name="gz::sim::systems::JointPositionController">
      <joint_name>gimbal_roll_joint</joint_name>
      <topic>/gimbal/joint1/cmd</topic>
      <p_gain>100</p_gain>
      <i_gain>0.0</i_gain>
      <d_gain>1</d_gain>
      <i_max>1</i_max>
      <i_min>-1</i_min>
      <cmd_max>1000</cmd_max>
      <cmd_min>-1000</cmd_min>
    </plugin>
    <plugin
        filename="gz-sim-joint-state-publisher-system"
        name="gz::sim::systems::JointStatePublisher">
      <joint_name>gimbal_roll_joint</joint_name>
      <topic>/gimbal/joint1/state</topic>
    </plugin>

    <!-- Gimbal pitch motor -->
    <link name="gimbal_pitch">
      <pose relative_to="gimbal_roll_bar">0.0 0.0175 0.01 -1.5708 0.0 0.0</pose>

      <inertial>
        <inertia>
          <ixx>0.00001</ixx>
          <ixy>0</ixy>
          <ixz>0</ixz>
          <iyy>0.00001</iyy>
          <iyz>0</iyz>
          <izz>0.00001</izz>
        </inertia>
        <mass>0.0001</mass>
      </inertial>

      <visual name="gimbal_pitch_visual">
        <geometry>
          <cylinder>
            <radius>0.015</radius>
            <length>0.015</length>
          </cylinder>
        </geometry>

        <material>
            <ambient>1.0 0.0 0.0 1</ambient>
            <diffuse>1.0 0.0 0.0 1</diffuse>
            <specular>1.0 0.0 0.0 1</specular>
        </material>
      </visual>

      <collision name="gimbal_pitch_collision">
        <geometry>
          <cylinder>
            <radius>0.015</radius>
            <length>0.015</length>
          </cylinder>
        </geometry>
      </collision>
    </link>

    <!-- Gimbal pitch bar -->
    <link name="gimbal_pitch_bar">
      <pose relative_to="gimbal_pitch">0.0 0.0 0.0 0.0 3.14 0.0</pose>

      <inertial>
        <inertia>
          <ixx>0.000001</ixx>
          <ixy>0</ixy>
          <ixz>0</ixz>
          <iyy>0.000001</iyy>
          <iyz>0</iyz>
          <izz>0.000001</izz>
        </inertia>
        <mass>0.00001</mass>
      </inertial>

      <visual name="gimbal_pitch_bar_visual">
        <geometry>
          <box>
            <size>0.02 0.02 0.10</size>
          </box>
        </geometry>

        <material>
          <ambient>0.0 0.0 0.0 1</ambient>
          <diffuse>0.0 0.0 0.0 1</diffuse>
          <specular>0.0 0.0 0.0 1</specular>
        </material>
      </visual>

      <!-- Camera0 -->
      <visual name="camera0_visual">
        <pose>0 0 0.05 1.5708 0 -1.5708</pose>

        <geometry>
          <box>
            <size>0.05 0.03 0.03</size>
          </box>
        </geometry>

        <material>
          <ambient>0.0 0.0 1.0 1</ambient>
          <diffuse>0.0 0.0 1.0 1</diffuse>
          <specular>0.0 0.0 1.0 1</specular>
        </material>
      </visual>
      <sensor name="camera0" type="camera">
        <pose>0 0 0.05 1.5708 0 -1.5708</pose>

        <topic>/gimbal/camera0</topic>
        <camera>
          <horizontal_fov>1.047</horizontal_fov>
          <image>
            <width>640</width>
            <height>640</height>
          </image>
        </camera>

        <always_on>1</always_on>
        <update_rate>10</update_rate>
        <visualize>true</visualize>
      </sensor>

      <!-- Camera1 -->
      <visual name="camera1_visual">
        <pose>0 0 -0.05 1.5708 0 -1.5708</pose>

        <geometry>
          <box>
            <size>0.05 0.03 0.03</size>
          </box>
        </geometry>

        <material>
          <ambient>0.0 0.0 1.0 1</ambient>
          <diffuse>0.0 0.0 1.0 1</diffuse>
          <specular>0.0 0.0 1.0 1</specular>
        </material>
      </visual>
      <sensor name="camera1" type="camera">
        <pose>0 0 -0.05 1.5708 0 -1.5708</pose>

        <topic>/gimbal/camera1</topic>
        <camera>
          <horizontal_fov>1.047</horizontal_fov>
          <image>
            <width>640</width>
            <height>640</height>
          </image>
        </camera>

        <always_on>1</always_on>
        <update_rate>10</update_rate>
        <visualize>true</visualize>
      </sensor>
    </link>

    <!-- Gimbal roll bar to gimbal pitch joint -->
    <joint name="gimbal_roll_bar_to_gimbal_pitch_joint" type="fixed">
      <parent>gimbal_roll_bar</parent>
      <child>gimbal_pitch</child>
    </joint>

    <!-- Gimbal pitch joint -->
    <joint name="gimbal_pitch_joint" type="revolute">
      <parent>gimbal_pitch</parent>
      <child>gimbal_pitch_bar</child>
      <axis>
        <xyz>0 0 1</xyz>
        <dynamics>
          <damping>1.0</damping>
        </dynamics>
      </axis>
    </joint>
    <plugin
        filename="gz-sim-joint-position-controller-system"
        name="gz::sim::systems::JointPositionController">
      <joint_name>gimbal_pitch_joint</joint_name>
      <topic>/gimbal/joint2/cmd</topic>
      <p_gain>10</p_gain>
      <i_gain>0.0</i_gain>
      <d_gain>0.5</d_gain>
      <i_max>1</i_max>
      <i_min>-1</i_min>
      <cmd_max>1000</cmd_max>
      <cmd_min>-1000</cmd_min>
    </plugin>
    <plugin
        filename="gz-sim-joint-state-publisher-system"
        name="gz::sim::systems::JointStatePublisher">
      <joint_name>gimbal_pitch_joint</joint_name>
      <topic>/gimbal/joint2/state</topic>
    </plugin>

    <plugin
        filename="libGimbalControllerPlugin"
        name="GimbalControllerPlugin">
      <joint0_cmd_topic>/gimbal/joint0/cmd</joint0_cmd_topic>
      <joint1_cmd_topic>/gimbal/joint1/cmd</joint1_cmd_topic>
      <joint2_cmd_topic>/gimbal/joint2/cmd</joint2_cmd_topic>
      <gimbal_mode_state_topic>/gimbal/mode/state</gimbal_mode_state_topic>
      <target_point_state_topic>/gimbal/target_point/state</target_point_state_topic>
      <target_attitude_state_topic>/gimbal/target_attitude/state</target_attitude_state_topic>
      <gimbal_mode_cmd_topic>/gimbal/mode/cmd</gimbal_mode_cmd_topic>
      <target_point_cmd_topic>/gimbal/target_point/cmd</target_point_cmd_topic>
      <target_attitude_cmd_topic>/gimbal/target_attitude/cmd</target_attitude_cmd_topic>
    </plugin>
  </model>
</sdf>
