<?xml version="1.0" ?>
<sdf version="1.6">
  <world name="default">
    <plugin name='gz::sim::systems::Physics' filename='gz-sim-physics-system'/>
    <plugin name='gz::sim::systems::UserCommands' filename='gz-sim-user-commands-system'/>
    <plugin name='gz::sim::systems::SceneBroadcaster' filename='gz-sim-scene-broadcaster-system'/>
    <plugin name='gz::sim::systems::Contact' filename='gz-sim-contact-system'/>
    <plugin name='gz::sim::systems::Imu' filename='gz-sim-imu-system'/>
    <plugin name='gz::sim::systems::Sensors' filename='gz-sim-sensors-system'>
      <render_engine>ogre2</render_engine>
    </plugin>

    <!-- LIGHTING -->
    <light type="directional" name="sun">
      <cast_shadows>true</cast_shadows>
      <pose>0 0 10 0 0 0</pose>
      <diffuse>1 1 1 1</diffuse>
      <specular>0.5 0.5 0.5 1</specular>
      <attenuation>
        <range>1000</range>
        <constant>0.9</constant>
        <linear>0.01</linear>
        <quadratic>0.001</quadratic>
      </attenuation>
      <direction>-0.5 0.1 -0.9</direction>
    </light>

    <!-- GROUND PLANE -->
    <model name="ground_plane">
      <static>true</static>
      <link name="link">
        <collision name="collision">
          <geometry>
            <plane>
              <normal>0 0 1</normal>
              <size>100 100</size>
            </plane>
          </geometry>
        </collision>
        <visual name="visual">
          <geometry>
            <plane>
              <normal>0 0 1</normal>
              <size>100 100</size>
            </plane>
          </geometry>
          <material>
            <ambient>0.8 0.8 0.8 1</ambient>
            <diffuse>0.8 0.8 0.8 1</diffuse>
            <specular>0.8 0.8 0.8 1</specular>
          </material>
        </visual>
      </link>
    </model>

    <!-- <!-1- MAV -1-> -->
    <!-- <include> -->
    <!--   <uri>model://x500</uri> -->
    <!--   <pose>0 0 0.5 0 0 0</pose> -->
    <!-- </include> -->

    <!-- ARPILGRID -->
    <include>
      <static>true</static>
      <uri>model://aprilgrid</uri>
      <pose>1 0.49 0.0 1.5708 0 -1.5708</pose>
    </include>

    <model name="gimbal">
      <pose>0.0 0.0 0.005 0.0 0.0 0.0</pose>
      <!-- <pose>0.0 0.0 0.5 0.5 0.0 0.0</pose> -->

      <!-- Gimbal base -->
      <link name="gimbal_base">
        <inertial>
          <inertia>
            <ixx>0.001</ixx>
            <ixy>0</ixy>
            <ixz>0</ixz>
            <iyy>0.001</iyy>
            <iyz>0</iyz>
            <izz>0.001</izz>
          </inertia>
          <mass>1.0</mass>
        </inertial>

        <visual name="gimbal_base_visual">
          <geometry>
            <box>
              <size>0.1 0.1 0.01</size>
            </box>
          </geometry>

          <material>
              <ambient>0.0 0.0 0.0 1</ambient>
              <diffuse>0.0 0.0 0.0 1</diffuse>
              <specular>0.0 0.0 0.0 1</specular>
          </material>
        </visual>

        <collision name="gimbal_base_collision">
          <geometry>
            <box>
              <size>0.1 0.1 0.01</size>
            </box>
          </geometry>
        </collision>
      </link>

      <!-- Gimbal yaw motor -->
      <link name="gimbal_yaw">
        <pose relative_to="gimbal_base">0.0 0.0 0.01225 0.0 0.0 0.0</pose>

        <inertial>
          <inertia>
            <ixx>0.0001</ixx>
            <ixy>0</ixy>
            <ixz>0</ixz>
            <iyy>0.0001</iyy>
            <iyz>0</iyz>
            <izz>0.0001</izz>
          </inertia>
          <mass>0.001</mass>
        </inertial>

        <visual name="gimbal_yaw_visual">
          <geometry>
            <cylinder>
              <radius>0.015</radius>
              <length>0.015</length>
            </cylinder>
          </geometry>

          <material>
              <ambient>1.0 0.0 0.0 1</ambient>
              <diffuse>1.0 0.0 0.0 1</diffuse>
              <specular>1.0 0.0 0.0 1</specular>
          </material>
        </visual>

        <collision name="gimbal_yaw_collision">
          <geometry>
            <cylinder>
              <radius>0.015</radius>
              <length>0.015</length>
            </cylinder>
          </geometry>
        </collision>
      </link>

      <!-- Gimbal base to yaw joint -->
      <joint name="gimbal_base_to_gimbal_yaw_joint" type="fixed">
        <parent>gimbal_base</parent>
        <child>gimbal_yaw</child>
      </joint>

      <!-- Gimbal yaw joint -->
      <joint name="gimbal_yaw_joint" type="revolute">
        <parent>gimbal_yaw</parent>
        <child>gimbal_yaw_bar</child>
        <axis>
          <xyz>0 0 1</xyz>
          <dynamics>
            <damping>1.0</damping>
          </dynamics>
        </axis>
      </joint>
      <plugin
          filename="gz-sim-joint-position-controller-system"
          name="gz::sim::systems::JointPositionController">
        <joint_name>gimbal_yaw_joint</joint_name>
        <topic>/gimbal/joint0/cmd</topic>
        <p_gain>10</p_gain>
        <i_gain>0.01</i_gain>
        <d_gain>0.5</d_gain>
        <i_max>1</i_max>
        <i_min>-1</i_min>
        <cmd_max>1000</cmd_max>
        <cmd_min>-1000</cmd_min>
      </plugin>
      <plugin
          filename="gz-sim-joint-state-publisher-system"
          name="gz::sim::systems::JointStatePublisher">
        <joint_name>gimbal_yaw_joint</joint_name>
        <topic>/gimbal/joint0/state</topic>
      </plugin>

      <!-- Gimbal yaw bar -->
      <link name="gimbal_yaw_bar">
        <pose relative_to="gimbal_yaw">0.0 0.0 0.0325 0.0 0.0 0.0</pose>

        <inertial>
          <inertia>
            <ixx>0.000001</ixx>
            <ixy>0</ixy>
            <ixz>0</ixz>
            <iyy>0.000001</iyy>
            <iyz>0</iyz>
            <izz>0.000001</izz>
          </inertia>
          <mass>0.00001</mass>
        </inertial>

        <visual name="gimbal_yaw_bar_visual">
          <geometry>
            <box>
              <size>0.02 0.02 0.05</size>
            </box>
          </geometry>

          <material>
              <ambient>0.0 0.0 0.0 1</ambient>
              <diffuse>0.0 0.0 0.0 1</diffuse>
              <specular>0.0 0.0 0.0 1</specular>
          </material>
        </visual>

        <collision name="gimbal_yaw_bar_collision">
          <pose>0.0 0.0 0.0 0 0 0</pose>
          <geometry>
            <box>
              <size>0.02 0.02 0.05</size>
            </box>
          </geometry>
        </collision>
      </link>

      <!-- Gimbal roll motor -->
      <link name="gimbal_roll">
        <pose relative_to="gimbal_yaw_bar">0.0175 0.0 0.01 0.0 1.5708 0.0</pose>

        <inertial>
          <inertia>
            <ixx>0.000001</ixx>
            <ixy>0</ixy>
            <ixz>0</ixz>
            <iyy>0.000001</iyy>
            <iyz>0</iyz>
            <izz>0.000001</izz>
          </inertia>
          <mass>0.00001</mass>
        </inertial>

        <visual name="gimbal_roll_visual">
          <geometry>
            <cylinder>
              <radius>0.015</radius>
              <length>0.015</length>
            </cylinder>
          </geometry>

          <material>
              <ambient>1.0 0.0 0.0 1</ambient>
              <diffuse>1.0 0.0 0.0 1</diffuse>
              <specular>1.0 0.0 0.0 1</specular>
          </material>
        </visual>

        <collision name="gimbal_roll_collision">
          <geometry>
            <cylinder>
              <radius>0.015</radius>
              <length>0.015</length>
            </cylinder>
          </geometry>
        </collision>
      </link>

      <!-- Gimbal roll bar -->
      <link name="gimbal_roll_bar">
        <pose relative_to="gimbal_roll">0.0 0.0 0.0325 0.0 0.0 0.0</pose>

        <inertial>
          <inertia>
            <ixx>0.000001</ixx>
            <ixy>0</ixy>
            <ixz>0</ixz>
            <iyy>0.000001</iyy>
            <iyz>0</iyz>
            <izz>0.000001</izz>
          </inertia>
          <mass>0.00001</mass>
        </inertial>

        <visual name="gimbal_roll_bar_visual">
          <geometry>
            <box>
              <size>0.02 0.02 0.05</size>
            </box>
          </geometry>

          <material>
              <ambient>0.0 0.0 0.0 1</ambient>
              <diffuse>0.0 0.0 0.0 1</diffuse>
              <specular>0.0 0.0 0.0 1</specular>
          </material>
        </visual>

        <collision name="gimbal_roll_bar_collision">
          <pose>0.0 0.0 0.0 0 0 0</pose>
          <geometry>
            <box>
              <size>0.02 0.02 0.05</size>
            </box>
          </geometry>
        </collision>
      </link>

      <!-- Gimbal yaw bar to roll joint -->
      <joint name="gimbal_yaw_bar_to_gimbal_roll_joint" type="fixed">
        <parent>gimbal_yaw_bar</parent>
        <child>gimbal_roll</child>
      </joint>

      <!-- Gimbal roll joint -->
      <joint name="gimbal_roll_joint" type="revolute">
        <parent>gimbal_roll</parent>
        <child>gimbal_roll_bar</child>
        <axis>
          <xyz>0 0 1</xyz>
          <dynamics>
            <damping>1.0</damping>
          </dynamics>
        </axis>
      </joint>
      <plugin
          filename="gz-sim-joint-position-controller-system"
          name="gz::sim::systems::JointPositionController">
        <joint_name>gimbal_roll_joint</joint_name>
        <topic>/gimbal/joint1/cmd</topic>
        <p_gain>10</p_gain>
        <i_gain>0.01</i_gain>
        <d_gain>0.5</d_gain>
        <i_max>1</i_max>
        <i_min>-1</i_min>
        <cmd_max>1000</cmd_max>
        <cmd_min>-1000</cmd_min>
      </plugin>
      <plugin
          filename="gz-sim-joint-state-publisher-system"
          name="gz::sim::systems::JointStatePublisher">
        <joint_name>gimbal_roll_joint</joint_name>
        <topic>/gimbal/joint1/state</topic>
      </plugin>

      <!-- Gimbal pitch motor -->
      <link name="gimbal_pitch">
        <pose relative_to="gimbal_roll_bar">0.0 0.0175 0.01 -1.5708 0.0 0.0</pose>

        <inertial>
          <inertia>
            <ixx>0.000001</ixx>
            <ixy>0</ixy>
            <ixz>0</ixz>
            <iyy>0.000001</iyy>
            <iyz>0</iyz>
            <izz>0.000001</izz>
          </inertia>
          <mass>0.00001</mass>
        </inertial>

        <visual name="gimbal_pitch_visual">
          <geometry>
            <cylinder>
              <radius>0.015</radius>
              <length>0.015</length>
            </cylinder>
          </geometry>

          <material>
              <ambient>1.0 0.0 0.0 1</ambient>
              <diffuse>1.0 0.0 0.0 1</diffuse>
              <specular>1.0 0.0 0.0 1</specular>
          </material>
        </visual>

        <collision name="gimbal_pitch_collision">
          <geometry>
            <cylinder>
              <radius>0.015</radius>
              <length>0.015</length>
            </cylinder>
          </geometry>
        </collision>
      </link>

      <!-- Gimbal pitch bar -->
      <link name="gimbal_pitch_bar">
        <pose relative_to="gimbal_pitch">0.0 0.0 0.0 0.0 0.0 0.0</pose>

        <inertial>
          <inertia>
            <ixx>0.000001</ixx>
            <ixy>0</ixy>
            <ixz>0</ixz>
            <iyy>0.000001</iyy>
            <iyz>0</iyz>
            <izz>0.000001</izz>
          </inertia>
          <mass>0.00001</mass>
        </inertial>

        <visual name="gimbal_pitch_bar_visual">
          <geometry>
            <box>
              <size>0.02 0.02 0.10</size>
            </box>
          </geometry>

          <material>
            <ambient>0.0 0.0 0.0 1</ambient>
            <diffuse>0.0 0.0 0.0 1</diffuse>
            <specular>0.0 0.0 0.0 1</specular>
          </material>
        </visual>

        <visual name="camera0_visual">
          <pose>0 0 0.05 1.5708 0 -1.5708</pose>

          <geometry>
            <box>
              <size>0.05 0.03 0.03</size>
            </box>
          </geometry>

          <material>
            <ambient>0.0 0.0 1.0 1</ambient>
            <diffuse>0.0 0.0 1.0 1</diffuse>
            <specular>0.0 0.0 1.0 1</specular>
          </material>
        </visual>
        <sensor name="camera0" type="camera">
          <pose>0 0 0.05 1.5708 0 -1.5708</pose>

          <topic>/gimbal/camera0</topic>
          <camera>
            <horizontal_fov>1.047</horizontal_fov>
            <image>
              <width>640</width>
              <height>640</height>
            </image>
          </camera>

          <always_on>1</always_on>
          <update_rate>10</update_rate>
          <visualize>true</visualize>
        </sensor>

        <visual name="camera1_visual">
          <pose>0 0 -0.05 1.5708 0 -1.5708</pose>

          <geometry>
            <box>
              <size>0.05 0.03 0.03</size>
            </box>
          </geometry>

          <material>
            <ambient>0.0 0.0 1.0 1</ambient>
            <diffuse>0.0 0.0 1.0 1</diffuse>
            <specular>0.0 0.0 1.0 1</specular>
          </material>
        </visual>
        <sensor name="camera1" type="camera">
          <pose>0 0 -0.05 1.5708 0 -1.5708</pose>

          <topic>/gimbal/camera1</topic>
          <camera>
            <horizontal_fov>1.047</horizontal_fov>
            <image>
              <width>640</width>
              <height>640</height>
            </image>
          </camera>

          <always_on>1</always_on>
          <update_rate>10</update_rate>
          <visualize>true</visualize>
        </sensor>
      </link>

      <!-- Gimbal roll bar to gimbal pitch joint -->
      <joint name="gimbal_roll_bar_to_gimbal_pitch_joint" type="fixed">
        <parent>gimbal_roll_bar</parent>
        <child>gimbal_pitch</child>
      </joint>

      <!-- Gimbal pitch joint -->
      <joint name="gimbal_pitch_joint" type="revolute">
        <parent>gimbal_pitch</parent>
        <child>gimbal_pitch_bar</child>
        <axis>
          <xyz>0 0 1</xyz>
          <dynamics>
            <damping>1.0</damping>
          </dynamics>
        </axis>
      </joint>
      <plugin
          filename="gz-sim-joint-position-controller-system"
          name="gz::sim::systems::JointPositionController">
        <joint_name>gimbal_pitch_joint</joint_name>
        <topic>/gimbal/joint2/cmd</topic>
        <p_gain>10</p_gain>
        <i_gain>0.01</i_gain>
        <d_gain>0.5</d_gain>
        <i_max>1</i_max>
        <i_min>-1</i_min>
        <cmd_max>1000</cmd_max>
        <cmd_min>-1000</cmd_min>
      </plugin>
      <plugin
          filename="gz-sim-joint-state-publisher-system"
          name="gz::sim::systems::JointStatePublisher">
        <joint_name>gimbal_pitch_joint</joint_name>
        <topic>/gimbal/joint2/state</topic>
      </plugin>

    </model>
  </world>
</sdf>
